Workbook

Sheet PARÁMETROS
A1: 🍺 CERVECERÍA B&E S.A.S. — MODELO MPS + MRP
A2: Parámetros del sistema
A4: PARÁMETROS DE PRODUCCIÓN | C4: DEMANDA Y LEAD TIMES
A5: Número de tanques | B5: 6 | C5: Pedido fijo / sabor / mes (L) | D5: 200 | E5: L/mes por sabor
A6: Capacidad por tanque (L) | B6: 120 | C6: Pedido fijo sem.1 / sabor (L) | D6: =D5/2 -> 100 | E6: L
A7: Capacidad semanal total (L) | B7: =B5*B6 -> 720 | C7: Pedido fijo sem.2 / sabor (L) | D7: =D5/2 -> 100 | E7: L
A8: Tiempo de fermentación (días) | B8: 7 | C8: Total pedido fijo / semana (L) | D8: =D6*B9 -> 600 | E8: L (sem.1 y sem.2)
A9: Número de sabores | B9: 6 | C9: Barrera de demanda (semanas) | D9: 2 | E9: semanas
A10: Capacidad botella (mL) | B10: 330 | C10: Horizonte de planificación (sem) | D10: 4 | E10: semanas
A11: Capacidad botella (L) | B11: =B10/1000 -> 0.33 | C11: Lead time Bogotá (días) | D11: 2 | E11: días
A12: Botellas por tanque | B12: =INT(B6/B11) -> 363 | C12: Lead time Armenia (días) | D12: 1 | E12: días
A15: INVENTARIO INICIAL — MATERIAS PRIMAS
A16: Materia Prima | B16: Inv. Inicial | C16: Unidad | D16: Stock Seguridad (Para lote de 80 L) en KG | E16: Lead Time (días) | F16: Unidad Compra | G16: Tamaño Unidad Compra
A17: Malta Pale Ale | B17: 54 | C17: kg | D17: =(RECETAS!B22*80)+(RECETAS!B22*80) -> 36 | E17: 2 | F17: Bultos | G17: 25 | H17: kg
A18: Malta Pilsen | B18: 50 | C18: kg | D18: =(RECETAS!D23*80)+(RECETAS!E23*80) -> 30.666667 | E18: 2 | F18: Bultos | G18: 25 | H18: kg
A19: Malta Chocolate | B19: 30 | C19: kg | D19: =(RECETAS!F24*80) -> 18.666667 | E19: 2 | F19: Bultos | G19: 25 | H19: kg
A20: Malta Roasted | B20: 25 | C20: kg | D20: =(RECETAS!G25*80) -> 15.333333 | E20: 2 | F20: Bultos | G20: 25 | H20: kg
A21: Lúpulo Magnum | B21: =1200/1000 -> 1.2 | C21: kg | D21: =(RECETAS!B26*80)+(RECETAS!C26*80)+(RECETAS!D26*80)+(RECETAS!E26*80)+(RECETAS!F26*80)+(RECETAS!G26*80) -> 1.1466667 | E21: 2 | F21: Bolsas | G21: 1 | H21: kg
A22: Levadura US-05 | B22: =500/1000 -> 0.5 | C22: kg | D22: =(RECETAS!B27*80)+(RECETAS!C27*80)+(RECETAS!D27*80)+(RECETAS!E27*80)+(RECETAS!F27*80)+(RECETAS!G27*80) -> 0.299 | E22: 2 | F22: Packs | G22: 0.5 | H22: kg
A23: Miel | B23: =4000/1000 -> 4 | C23: kg | D23: =(RECETAS!C28*80)+(RECETAS!D28*80) -> 6.6666667 | E23: 1 | F23: Frasco | G23: 27 | H23: kg
A24: Botellas 330mL | B24: 400 | C24: botellas | D24: 242 | E24: 1 | F24: Cajas | G24: 24 | H24: botellas
A25: Tapas | B25: 500 | C25: tapas | D25: 242 | E25: 1 | F25: Paquetes | G25: 100 | H25: tapas

Sheet RECETAS
A1: RECETAS DE PRODUCCIÓN — Insumos por lote de 120L
A2: 120
A4: Materia Prima / Unidad | B4: IPA (Pijao) | C4: IPA Honey | D4: Honey Golden Ale | E4: Golden Ale | F4: Porter | G4: Iris Red Ale | H4: Sem 1 | I4: Sem 2
A5: Malta Pale Ale (kg) | B5: 27 | C5: 26 | D5: — | E5: — | F5: — | G5: — | H5: =B5+C5 -> 53 | I5: =H5*2 -> 106
A6: Malta Pilsen (kg) | B6: — | C6: — | D6: 24 | E6: 22 | F6: — | G6: — | H6: =D6+E6 -> 46 | I6: =H6*2 -> 92
A7: Malta Chocolate (kg) | B7: — | C7: — | D7: — | E7: — | F7: 28 | G7: — | H7: =F7 -> 28 | I7: =H7*2 -> 56
A8: Malta Roasted (kg) | B8: — | C8: — | D8: — | E8: — | F8: — | G8: 23 | H8: =G8 -> 23 | I8: =H8*2 -> 46
A9: Lúpulo Magnum (kg) | B9: =595/1000 -> 0.595 | C9: =540/1000 -> 0.54 | D9: =165/1000 -> 0.165 | E9: =165/1000 -> 0.165 | F9: =135/1000 -> 0.135 | G9: =120/1000 -> 0.12
A10: Levadura US-05 (kg) | B10: =(11.5*7)/1000 -> 0.0805 | C10: =(11.5*7)/1000 -> 0.0805 | D10: =(11.5*6)/1000 -> 0.069 | E10: =(11.5*6)/1000 -> 0.069 | F10: =(11.5*7)/1000 -> 0.0805 | G10: =(11.5*6)/1000 -> 0.069
A11: Miel (kg) | B11: — | C11: =5.5 -> 5.5 | D11: =4.5 -> 4.5 | E11: — | F11: — | G11: —
A12: Botellas 330mL (ud) | B12: 363 | C12: 363 | D12: 363 | E12: 363 | F12: 363 | G12: 363
A13: Tapas corona (ud) | B13: 363 | C13: 363 | D13: 363 | E13: 363 | F13: 363 | G13: 363
A14: Agua (L) | B14: 380 | C14: 380 | D14: 380 | E14: 380 | F14: 380 | G14: 380
A18: RECETAS DE PRODUCCIÓN — Insumos pora producir 1 L
A19: Cantidades para 1 L
A21: Materia Prima / Unidad | B21: IPA (Pijao) | C21: IPA Honey | D21: Honey Golden Ale | E21: Golden Ale | F21: Porter | G21: Iris Red Ale
A22: Malta Pale Ale (kg) | B22: =27/A2 -> 0.225 | C22: =26/A2 -> 0.21666667 | D22: — | E22: — | F22: — | G22: — | I22: Sumar en los resquerimientos el echo de que algunas maltas se repiden igual en los otros casos
A23: Malta Pilsen (kg) | B23: — | C23: — | D23: =24/A2 -> 0.2 | E23: =22/A2 -> 0.18333333 | F23: — | G23: —
A24: Malta Chocolate (kg) | B24: — | C24: — | D24: — | E24: — | F24: =28/A2 -> 0.23333333 | G24: —
A25: Malta Roasted (kg) | B25: — | C25: — | D25: — | E25: — | F25: — | G25: =23/A2 -> 0.19166667
A26: Lúpulo Magnum (kg) | B26: =(595/1000)/A2 -> 0.0049583333 | C26: =(540/1000)/A2 -> 0.0045 | D26: =(165/1000)/A2 -> 0.001375 | E26: =(165/1000)/A2 -> 0.001375 | F26: =(135/1000)/A2 -> 0.001125 | G26: =(120/1000)/A2 -> 0.001
A27: Levadura US-05 (kg) | B27: =((11.5*7)/1000)/A2 -> 0.00067083333 | C27: =((11.5*7)/1000)/A2 -> 0.00067083333 | D27: =((11.5*6)/1000)/A2 -> 0.000575 | E27: =((11.5*6)/1000)/A2 -> 0.000575 | F27: =((11.5*7)/1000)/A2 -> 0.00067083333 | G27: =((11.5*6)/1000)/A2 -> 0.000575
A28: Miel (kg) | B28: — | C28: =(5.5)/A2 -> 0.045833333 | D28: =(4.5)/A2 -> 0.0375 | E28: — | F28: — | G28: —
A29: Agua (L) | B29: =380/$A$2 -> 3.1666667 | C29: =380/$A$2 -> 3.1666667 | D29: =380/$A$2 -> 3.1666667 | E29: =380/$A$2 -> 3.1666667 | F29: =380/$A$2 -> 3.1666667 | G29: =380/$A$2 -> 3.1666667
A30: Botellas 330mL (ud) | B30: =3 -> 3 | C30: 3 | D30: 3 | E30: 3 | F30: 3 | G30: 3
A31: Tapas corona (ud) | B31: 3 | C31: 3 | D31: 3 | E31: 3 | F31: 3 | G31: 3

Sheet MPS — PEDIDOS FIJOS
A1: PROGRAMA MAESTRO DE PRODUCCIÓN — CANAL GASTROBARES (Pedidos Fijos)
A2: Barrera de demanda: 2 semanas | Tamaño capacidad de lote: 120 L | Inventario inicial: 50 L por sabor
A3: RESUMEN CONSOLIDADO — TODOS LOS SABORES
A4: Total lotes sem.1 | B4: 6 | C4: lotes (6 sabores)
A5: Total lotes sem.2 | B5: 6 | C5: lotes (6 sabores)
A6: Total litros fijos/mes | B6: =PARÁMETROS!B7*2 -> 1440 | C6: L entregados gastrobares
A7: Litros overflow sem.1 (libre) | B7: =720-600 -> 120 | C7: L libres para botellar
A8: Litros overflow sem.2 (libre) | B8: =720-600 -> 120 | C8: L libres para botellar
B10: =B7/6 -> 20 | C10: L x sabor

Sheet MPS — CANAL BOTELLAS (2)
A1: PROGRAMA MAESTRO — CANAL BOTELLAS 330mL (Pronóstico sem.3 y sem.4)
A2: Sem.1 y Sem.2: overflow embotellado (~363 bot/sem) | Sem.3 y Sem.4: lotes dedicados según pronóstico
A4: Fila | B4: Semana 0 | C4: Semana 1 | D4: Semana 2 | E4: Semana 3 | F4: Semana 4 | G4: TOTAL MES | H4: PARÁMETROS BOTELLAS
A5: Pronóstico (botellas) | B5: — | C5: 509 | D5: 510 | E5: 510 | F5: 511 | G5: =SUM(C5:F5) -> 2040 | H5: Pronóstico botellas/sem (bot) | I5: =AVERAGE(C5:F5) -> 510 | J5: Aprox.
C6: =C5-H9 -> 145.36364 | D6: =D5-H11 -> 146.36364
C7: Entonces | D7: =C5-H9 -> 145.36364
A8: Inventario inicial producto terminado | D8: Litros | E8: ml/Lt | F8: Cant. Ml | G8: ml de una botella | H8: Botellas que salen | I8: Botellas por sabor | M8: Botellas semana 1 y 2 | N8: Botellas semana 3 y 4
A9: 300 | C9: Botellas resultantes de la primera semana | D9: ='MPS — PEDIDOS FIJOS'!B7 -> 120 | E9: 1000 | F9: =D9*E9 -> 120000 | G9: 330 | H9: =F9/G9 -> 363.63636 | I9: =H9/6 -> 60.606061 | M9: =H9+H11 -> 727.27273 | N9: =H13-M9 -> 1454.5455
A10: Inventario de PT luego de la semana 1 | D10: Litros | E10: ml/Lt | F10: Cant. Ml | G10: ml de una botella | H10: Botellas que salen | I10: Botellas por sabor | R10: =(G5*330)/1000 -> 673.2
A11: =A9-C6 -> 154.63636 | C11: Botellas resultantes de la segunda semana | D11: ='MPS — PEDIDOS FIJOS'!B8 -> 120 | E11: 1000 | F11: =D11*E11 -> 120000 | G11: 330 | H11: =F11/G11 -> 363.63636 | I11: =H11/6 -> 60.606061 | M11: =H13-G5 -> 141.81818 | N11: =M11+A9 -> 441.81818
A12: Inventario de PT luego de la semana 2 | D12: Litros | E12: ml/Lt | F12: Cant. Ml | G12: ml de una botella | H12: Botellas que salen | I12: Botellas por sabor
A13: =A11-D6 -> 8.2727273 | C13: Botellas a Producir en el mes | D13: =720 -> 720 | E13: 1000 | F13: =D13*E13 -> 720000 | G13: 330 | H13: =F13/G13 -> 2181.8182 | I13: =H13/6 -> 363.63636 | L13: Inventario de producto terminado para el siguiente mes | M13: =M18+M20 -> 441.81818 | N13: =(M13*330)/1000 -> 145.8 | P13: =1920-N13 -> 1774.2
D17: Litros | E17: ml/Lt | F17: Cant. Ml | G17: ml de una botella | H17: Botellas que salen | I17: Botellas por sabor
C18: Botellas a Producir para semana 3 y 4 | D18: 480 | E18: 1000 | F18: =D18*E18 -> 480000 | G18: 330 | H18: =F18/G18 -> 1454.5455 | I18: =H18/6 -> 242.42424 | L18: Valor resultado de las botellas que salen de la semana 3 y 4 menos los pronosticos de esas dos semanas | M18: =H18-E5-F5 -> 433.54545
D19: Litros | E19: ml/Lt | F19: Cant. Ml | G19: ml de una botella | H19: Botellas que salen | I19: Botellas x sabor si se divide las dos semanas
C20: Botellas a Producir por sabor en semana 3 | D20: 80 | E20: 1000 | F20: =D20*E20 -> 80000 | G20: 330 | H20: =F20/G20 -> 242.42424 | I20: =H20/2 -> 121.21212 | L20: Valor resultado de inventario de PT, donde ya se saco para cumplir pronostico de semana 1 y 2 | M20: =A13 -> 8.2727273
E25: =D26*2 -> 336
C26: Botellas a Producir por sabor en semana 3 | D26: 168 | E26: 1000 | F26: =D26*E26 -> 168000 | G26: 330 | H26: =F26/G26 -> 509.09091 | I26: =H26/2 -> 254.54545
D27: =D26+D13 -> 888
B31: PRONÓSTICO DE VENTAS Y BALANCE DE INVENTARIO — BOTELLAS
C32: Semana 0 | D32: Semana 1 | E32: Semana 2 | F32: Semana 3 | G32: Semana 4 | H32: TOTAL MES
B33: Pronóstico ventas (botellas) | C33: — | D33: =C5 -> 509 | E33: =D5 -> 510 | F33: =E5 -> 510 | G33: =F5 -> 511 | H33: =SUM(D33:G33) -> 2040
B34: Pronóstico ventas (litros) | C34: — | D34: =(D33*330)/1000 -> 167.97 | E34: =(E33*330)/1000 -> 168.3 | F34: =(F33*330)/1000 -> 168.3 | G34: =(G33*330)/1000 -> 168.63 | H34: =(H33*330)/1000 -> 673.2
B35: Inventario PT (botellas) al INICIO | C35: 300 | D35: — | E35: — | F35: — | G35: —
B36: Inventario PT (botellas) al FINAL | C36: — | D36: =A11 -> 154.63636 | E36: =A13 -> 8.2727273 | F36: =H18-F33+E36 -> 952.81818 | G36: =F36-G33 -> 441.81818
B37: Inventario PT (litros) al INICIO | C37: =(C35*330)/1000 -> 99 | D37: — | E37: — | F37: — | G37: —
B38: Inventario PT (litros) al FINAL | C38: — | D38: =(A11*330)/1000 -> 51.03 | E38: =(A13*330)/1000 -> 2.73 | F38: =D18-F34+E38 -> 314.43 | G38: =F38-G34 -> 145.8
B40: Litros producidos en las 4 semanas
B41: Concepto | C41: Semana 1 | D41: Semana 2 | E41: Semana 3 | F41: Semana 4 | G41: TOTAL MES | H41: % del total | I41: Tipo | J41: Notas
B42: Pedidos fijos — Barril (L) | C42: 600 | D42: 600 | E42: 0 | F42: 0 | G42: =SUM(C42:F42) -> 1200 | H42: =G42/G46 -> 0.625 | I42: Fija | J42: 100 L/sabor × 6 sab × 2 bares
B43: Overflow embotellado barril | C43: 120 | D43: 120 | E43: 0 | F43: 0 | G43: =SUM(C43:F43) -> 240 | H43: =G43/G46 -> 0.125 | I43: Overflow | J43: 720L − 600L = 120L sobrante/sem
B44: Producción según pronosticos | C44: 0 | D44: 0 | E44: 480 | F44: 0 | G44: =SUM(C44:F44) -> 480 | H44: =G44/G46 -> 0.25 | I44: Pronóstico | J44: Realmente se producen los 480 (suma de sem. 3 y 4) se producen en la sem. 3. pero aca es para entender.
B45: PRODUCCIÓN TOTAL (L) | C45: =SUM(C41:C44) -> 720 | D45: =SUM(D41:D44) -> 720 | E45: =SUM(E41:E44) -> 480 | F45: =SUM(F41:F44) -> 0 | G45: =SUM(G41:G44) -> 1920 | H45: 100% | I45: —
B46: Capacidad producida en el mes (L) | C46: 720 | D46: 720 | E46: 480 | F46: 0 | G46: =SUM(C46:F46) -> 1920 | H46: =G46/(720*4) -> 0.66666667 | J46: 720L × 4 sem = 2.880L cap. teórica
B49: RESUMEN DEMANDA SOLICITADA POR SEMANA
B50: Canal | C50: Semana 1 | D50: Semana 2 | E50: Semana 3 | F50: Semana 4 | G50: TOTAL MES
B51: Pedidos fijos — Barril (L) | C51: =C42 -> 600 | D51: =D42 -> 600 | E51: 0 | F51: 0 | G51: =SUM(C51:F51) -> 1200
B52: Pronosticos (L) | C52: =D34 -> 167.97 | D52: =E34 -> 168.3 | E52: =F34 -> 168.3 | F52: =G34 -> 168.63 | G52: =SUM(C52:F52) -> 673.2
B53: TOTAL (L) | C53: =SUM(C51:C52) -> 767.97 | D53: =SUM(D51:D52) -> 768.3 | E53: =SUM(E51:E52) -> 168.3 | F53: =SUM(F51:F52) -> 168.63 | G53: =SUM(C53:F53) -> 1873.2
B55: Inventario PT (litros) al FINAL | C55: =G46-G53+C37 -> 145.8
...
